<?xml version="1.0"?>
<robot name="CPRMover4">
  
  <link name="base_link">
    <visual>
      <geometry>
        <cylinder length="0.02" radius="0.1"/>
      </geometry>
	<origin rpy="0 0 0" xyz="0 0 0.01"/>
      <material name="black">
        <color rgba="0 0 0 0.9"/>
      </material>
    </visual>
  </link>
  <link name="A1fixed">
    <visual>
      <geometry>
        <cylinder length="0.13" radius="0.05"/>
      </geometry>
	<origin rpy="0 0 0" xyz="0 0 0.065"/>
      <material name="white">
        <color rgba="1 1 1 0.9"/>
      </material>
    </visual>
  </link>
 <joint name="basetoA1fixed" type="fixed">
    <parent link="base_link"/>
    <child link="A1fixed"/>
    <origin xyz="0 0 .02"/>
  </joint>


 <link name="Body1">
    <visual>
      <geometry>
	<cylinder length="0.13" radius="0.05"/>
      </geometry>
      <origin rpy="1.552 0 0" xyz="0 0 0"/>
      <material name="white">
        <color rgba="1 1 1 0.9"/>
      </material>
    </visual>
  </link>

<link name="Body2">
    <visual>
      <geometry>
	<cylinder length="0.01" radius="0.05"/>
      </geometry>
      <origin rpy="1.552 0 0" xyz="0 0.07 0"/>
      <material name="white">
        <color rgba="1 1 1 0.9"/>
      </material>
    </visual>
  </link>
<link name="UpperArm">
    <visual>
      <geometry>
	<box size="0.04 0.015 .25"/>
      </geometry>
      <origin rpy="0 0 0" xyz="0.0 0.07 0.095"/>
      <material name="white">
        <color rgba="1 1 1 0.9"/>
      </material>
    </visual>
  </link>
<link name="Body2Oben">
    <visual>
      <geometry>
	<cylinder length="0.13" radius="0.05"/>
      </geometry>
      <origin rpy="1.552 0 0" xyz="0 0.01 0.19"/>
      <material name="white">
        <color rgba="1 1 1 0.9"/>
      </material>
    </visual>
  </link>

  <joint name="A2basetoA2fixed" type="fixed">
    <parent link="Body2"/>
    <child link="UpperArm"/>
    <origin xyz="0 0 0"/>
  </joint>
  <joint name="A2ArmtoA2Oben" type="fixed">
    <parent link="Body2"/>
    <child link="Body2Oben"/>
    <origin xyz="0 0 0"/>
  </joint>




<link name="Body3">
    <visual>
      <geometry>
	<cylinder length="0.01" radius="0.05"/>
      </geometry>
      <origin rpy="1.552 0 0" xyz="0 -0.07 0"/>
      <material name="white">
        <color rgba="1 1 1 0.9"/>
      </material>
    </visual>
  </link>

<link name="LowerArm">
    <visual>
      <geometry>
	<box size="0.04 0.015 .28"/>
      </geometry>
      <origin rpy="0 0 0" xyz="0.0 -0.07 0.11"/>
      <material name="white">
        <color rgba="1 1 1 0.9"/>
      </material>
    </visual>
  </link>
<link name="Body3Oben">
    <visual>
      <geometry>
	<cylinder length="0.01" radius="0.05"/>
      </geometry>
      <origin rpy="1.552 0 0" xyz="0 -0.07 0.22"/>
      <material name="white">
        <color rgba="1 1 1 0.9"/>
      </material>
    </visual>
  </link>
  <joint name="A3basetoA3fixed" type="fixed">
    <parent link="Body3"/>
    <child link="LowerArm"/>
    <origin xyz="0 0 0"/>
  </joint>
<joint name="A3basetoA3oben" type="fixed">
    <parent link="Body3"/>
    <child link="Body3Oben"/>
    <origin xyz="0 0 0"/>
  </joint>

 

 
<link name="Body4">
    <visual>
      <geometry>
	<cylinder length="0.13" radius="0.05"/>
      </geometry>
      <origin rpy="1.552 0 0" xyz="0 0 0"/>
      <material name="white">
        <color rgba="1 1 1 0.9"/>
      </material>
    </visual>
  </link>
<link name="GripperBody">
    <visual>
      <geometry>
	<box size="0.03 0.06 .03"/>
      </geometry>
      <origin rpy="0 0 0" xyz="0.0 0.0 0.0"/>
      <material name="gray">
        <color rgba="0.3 0.3 0.3 0.9"/>
      </material>
    </visual>
  </link>
<link name="GripperFinger1">
    <visual>
      <geometry>
	<box size="0.01 0.01 .07"/>
      </geometry>
      <origin rpy="0.1 0 0" xyz="0.0 0.00 0.04"/>
      <material name="gray">
        <color rgba="1 1 1 0.9"/>
      </material>
    </visual>
  </link>
<link name="GripperFinger2">
    <visual>
      <geometry>
	<box size="0.01 0.01 .07"/>
      </geometry>
      <origin rpy="-0.1 0 0" xyz="0.00 0.00 0.04"/>
      <material name="gray">
        <color rgba="1 1 1 0.9"/>
      </material>
    </visual>
  </link>
<joint name="Gripper1" type="fixed">
    <parent link="Body4"/>
    <child link="GripperBody"/>
    <origin xyz="0 0 .05"/>
  </joint>
<joint name="Gripper2" type="fixed">
    <parent link="GripperBody"/>
    <child link="GripperFinger1"/>
    <origin xyz="0 0.01 0"/>
  </joint>
<joint name="Gripper3" type="fixed">
    <parent link="GripperBody"/>
    <child link="GripperFinger2"/>
    <origin xyz="0 -0.01 0"/>
  </joint>



<joint name="Joint0" type="continuous">
    <axis xyz="0 0 1"/>
    <parent link="base_link"/>
    <child link="Body1"/>
    <origin rpy="0 0 0" xyz="0 0 0.1925"/>
    <limit effort="100" velocity="100"/>
    <joint_properties damping="0.0" friction="0.0"/>
  </joint>
<joint name="Joint1" type="continuous">
    <axis xyz="0 1 0"/>
    <parent link="Body1"/>
    <child link="Body2"/>
    <origin rpy="0 0 0" xyz="0 0 0"/>
    <limit effort="100" velocity="100"/>
    <joint_properties damping="0.0" friction="0.0"/>
  </joint>

<joint name="Joint2" type="continuous">
    <axis xyz="0 1 0"/>
    <parent link="Body2"/>
    <child link="Body3"/>
    <origin rpy="0 0 0" xyz="0 0 0.19"/>
    <limit effort="100" velocity="100"/>
    <joint_properties damping="0.0" friction="0.0"/>
  </joint>
 <joint name="Joint3" type="continuous">
    <axis xyz="0 1 0"/>
    <parent link="Body3"/>
    <child link="Body4"/>
    <origin rpy="0 0 0" xyz="0 0 0.22"/>
    <limit effort="100" velocity="100"/>
    <joint_properties damping="0.0" friction="0.0"/>
  </joint>

 
  

  

</robot>

