<?xml version="1.0"?>
<robot xmlns:xacro="http://ros.org/wiki/xacro" name="CPRSRA1000HD">

<!-- URDF file for the Commonplace Robotics SRA1000HD robot arm -->
<!-- Version 1.1 from Oct. 5th, 2016.  -->
  
  <link name="base_link">
    <visual>
	<origin rpy="0 0 0" xyz="0 0 0.0"/>
      <geometry>
	<mesh filename="package://cpr_rviz_plugin/GeometryCPRSRA1000HD/Joint0.obj" scale="0.001 0.001 0.001"/>
      </geometry>
      <material name="black">
        <color rgba="0 0 0 0.8"/>
      </material>
    </visual>
    <collision>
      <origin xyz="0 0 0" rpy="0 0 0" />
      <geometry>
        <mesh filename="package://cpr_rviz_plugin/GeometryCPRSRA1000HD/Joint0Coll.obj" scale="0.001 0.001 0.001"/>
      </geometry>
    </collision>
  </link>

 <link name="geoJoint1">
    <visual>
	<origin rpy="0 0 0" xyz="0 0 0.0"/>
      <geometry>
	<mesh filename="package://cpr_rviz_plugin/GeometryCPRSRA1000HD/Joint1.obj" scale="0.001 0.001 0.001"/>
      </geometry>
      <material name="black">
        <color rgba="0 0 0 0.8"/>
      </material>
    </visual>
    <collision>
      <origin xyz="0 0 0" rpy="0 0 0" />
      <geometry>
        <mesh filename="package://cpr_rviz_plugin/GeometryCPRSRA1000HD/Joint1Coll.obj" scale="0.001 0.001 0.001"/>
      </geometry>
    </collision>
  </link>

 <link name="geoJoint2">
    <visual>
	<origin rpy="0 0 0" xyz="0 0 0.0"/>
      <geometry>
	<mesh filename="package://cpr_rviz_plugin/GeometryCPRSRA1000HD/Joint2.obj" scale="0.001 0.001 0.001"/>
      </geometry>
      <material name="black">
        <color rgba="0 0 0 0.8"/>
      </material>
    </visual>
    <collision>
      <origin xyz="0 0 0" rpy="0 0 0" />
      <geometry>
        <mesh filename="package://cpr_rviz_plugin/GeometryCPRSRA1000HD/Joint2Coll.obj" scale="0.001 0.001 0.001"/>
      </geometry>
    </collision>
  </link>

 <link name="geoJoint3">
    <visual>
	<origin rpy="0 0 0" xyz="0 0 0.0"/>
      <geometry>
	<mesh filename="package://cpr_rviz_plugin/GeometryCPRSRA1000HD/Joint3.obj" scale="0.001 0.001 0.001"/>
      </geometry>
      <material name="black">
        <color rgba="0 0 0 0.8"/>
      </material>
    </visual>
    <collision>
      <origin xyz="0 0 0" rpy="0 0 0" />
      <geometry>
        <mesh filename="package://cpr_rviz_plugin/GeometryCPRSRA1000HD/Joint3Coll.obj" scale="0.001 0.001 0.001"/>
      </geometry>
    </collision>
  </link>

 <link name="geoJoint4">
    <visual>
	<origin rpy="0 0 0" xyz="0 0 0.0"/>
      <geometry>
	<mesh filename="package://cpr_rviz_plugin/GeometryCPRSRA1000HD/Joint4.obj" scale="0.001 0.001 0.001"/>
      </geometry>
      <material name="black">
        <color rgba="0 0 0 0.8"/>
      </material>
    </visual>
    <collision>
      <origin xyz="0 0 0" rpy="0 0 0" />
      <geometry>
        <mesh filename="package://cpr_rviz_plugin/GeometryCPRSRA1000HD/Joint4Coll.obj" scale="0.001 0.001 0.001"/>
      </geometry>
    </collision>
  </link>

 <link name="geoJoint5">
    <visual>
	<origin rpy="0 0 0" xyz="0 0 0.0"/>
      <geometry>
	<mesh filename="package://cpr_rviz_plugin/GeometryCPRSRA1000HD/Joint5.obj" scale="0.001 0.001 0.001"/>
      </geometry>
      <material name="black">
        <color rgba="0 0 0 0.8"/>
      </material>
    </visual>
    <collision>
      <origin xyz="0 0 0" rpy="0 0 0" />
      <geometry>
        <mesh filename="package://cpr_rviz_plugin/GeometryCPRSRA1000HD/Joint5Coll.obj" scale="0.001 0.001 0.001"/>
      </geometry>
    </collision>
  </link>

 <link name="geoJoint6">
    <visual>
	<origin rpy="0 0 0" xyz="0 0 0.0"/>
      <geometry>
	<mesh filename="package://cpr_rviz_plugin/GeometryCPRSRA1000HD/Joint6.obj" scale="0.001 0.001 0.001"/>
      </geometry>
      <material name="black">
        <color rgba="0 0 0 0.8"/>
      </material>
    </visual>
    <collision>
      <origin xyz="0 0 0" rpy="0 0 0" />
      <geometry>
        <mesh filename="package://cpr_rviz_plugin/GeometryCPRSRA1000HD/Joint6Coll.obj" scale="0.001 0.001 0.001"/>
      </geometry>
    </collision>
  </link>

<link name="gripperBody">
    <visual>
	<origin rpy="0 0 0" xyz="0 0 0.0"/>
      <geometry>
	<mesh filename="package://cpr_rviz_plugin/GeometryCPRSRA1000HD/GripperBase.obj" scale="0.001 0.001 0.001"/>
      </geometry>
      <material name="black">
        <color rgba="0 0 0 0.8"/>
      </material>
    </visual>
    <collision>
      <origin xyz="0 0 0" rpy="0 0 0" />
      <geometry>
        <mesh filename="package://cpr_rviz_plugin/GeometryCPRSRA1000HD/GripperBaseColl.obj" scale="0.001 0.001 0.001"/>
      </geometry>
    </collision>
  </link>

<link name="gripperFinger1">
    <visual>
	<origin rpy="0 0 0" xyz="0 0 0.0"/>
      <geometry>
	<mesh filename="package://cpr_rviz_plugin/GeometryCPRSRA1000HD/GripperFinger.obj" scale="0.001 0.001 0.001"/>
      </geometry>
      <material name="black">
        <color rgba="0 0 0 0.8"/>
      </material>
    </visual>
    <collision>
      <origin xyz="0 0 0" rpy="0 0 0" />
      <geometry>
        <mesh filename="package://cpr_rviz_plugin/GeometryCPRSRA1000HD/GripperFingerColl.obj" scale="0.001 0.001 0.001"/>
      </geometry>
    </collision>
  </link>

<link name="gripperFinger2">
    <visual>
	<origin rpy="0 0 0" xyz="0 0 0.0"/>
      <geometry>
	<mesh filename="package://cpr_rviz_plugin/GeometryCPRSRA1000HD/GripperFinger.obj" scale="0.001 0.001 0.001"/>
      </geometry>
      <material name="black">
        <color rgba="0 0 0 0.8"/>
      </material>
    </visual>
 <collision>
      <origin xyz="0 0 0" rpy="0 0 0" />
      <geometry>
        <mesh filename="package://cpr_rviz_plugin/GeometryCPRSRA1000HD/GripperFingerColl.obj" scale="0.001 0.001 0.001"/>
      </geometry>
    </collision>
  </link>






<joint name="Joint0" type="continuous">
    <axis xyz="0 0 1"/>
    <parent link="base_link"/>
    <child link="geoJoint1"/>
    <origin rpy="0 0 0" xyz="0 0 0.122"/>
    <limit effort="100" velocity="30"/>
    <joint_properties damping="0.0" friction="0.0"/>
  </joint>
<joint name="Joint1" type="continuous">
    <axis xyz="0 1 0"/>
    <parent link="geoJoint1"/>
    <child link="geoJoint2"/>
    <origin rpy="0 0 0" xyz="0 0 0.076"/>
    <limit effort="100" velocity="100"/>
    <joint_properties damping="0.0" friction="0.0"/>
  </joint>

<joint name="Joint2" type="continuous">
    <axis xyz="0 1 0"/>
    <parent link="geoJoint2"/>
    <child link="geoJoint3"/>
    <origin rpy="0 1.57 0" xyz="0 0 0.350"/>
    <limit effort="100" velocity="100"/>
    <joint_properties damping="0.0" friction="0.0"/>
  </joint>
 <joint name="Joint3" type="continuous">
    <axis xyz="0 0 1"/>
    <parent link="geoJoint3"/>
    <child link="geoJoint4"/>
    <origin rpy="0 0 3.141" xyz="-0.045 0 0.400"/>
    <limit effort="100" velocity="100"/>
    <joint_properties damping="0.0" friction="0.0"/>
  </joint>
<joint name="Joint4" type="continuous">
    <axis xyz="0 1 0"/>
    <parent link="geoJoint4"/>
    <child link="geoJoint5"/>
    <origin rpy="0 0 -3.141" xyz="0 0 0.0"/>
    <limit effort="100" velocity="100"/>
    <joint_properties damping="0.0" friction="0.0"/>
  </joint>
<joint name="Joint5" type="continuous">
    <axis xyz="0 0 1"/>
    <parent link="geoJoint5"/>
    <child link="geoJoint6"/>
    <origin rpy="0 0 0" xyz="0.0 0 0.060"/>
    <limit effort="100" velocity="100"/>
    <joint_properties damping="0.0" friction="0.0"/>
  </joint>

<joint name="GripperFixed" type="fixed">
    <parent link="geoJoint6"/>
    <child link="gripperBody"/>
    <origin rpy="0 0 0" xyz="0 0 0"/>
  </joint>
<joint name="Gripper1" type="continuous">
    <axis xyz="1 0 0"/>
    <parent link="gripperBody"/>
    <child link="gripperFinger1"/>
    <origin rpy="0 0 3.141" xyz="0.0 0.01 0.03"/>
    <limit effort="100" velocity="100"/>
    <joint_properties damping="0.0" friction="0.0"/>
  </joint>
<joint name="Gripper2" type="continuous">
    <axis xyz="1 0 0"/>
    <parent link="gripperBody"/>
    <child link="gripperFinger2"/>
     <origin rpy="0 0 0" xyz="0.0 -0.01 0.03"/>
    <limit effort="100" velocity="100"/>
    <joint_properties damping="0.0" friction="0.0"/>
  </joint>

 
  

  

</robot>

